Traceback (most recent call last):
  File "/home/flavus/Projects/phd/venv/lib/python3.9/site-packages/jupyter_cache/executors/utils.py", line 51, in single_nb_execution
    executenb(
  File "/home/flavus/Projects/phd/venv/lib/python3.9/site-packages/nbclient/client.py", line 1093, in execute
    return NotebookClient(nb=nb, resources=resources, km=km, **kwargs).execute()
  File "/home/flavus/Projects/phd/venv/lib/python3.9/site-packages/nbclient/util.py", line 84, in wrapped
    return just_run(coro(*args, **kwargs))
  File "/home/flavus/Projects/phd/venv/lib/python3.9/site-packages/nbclient/util.py", line 62, in just_run
    return loop.run_until_complete(coro)
  File "/usr/lib/python3.9/asyncio/base_events.py", line 642, in run_until_complete
    return future.result()
  File "/home/flavus/Projects/phd/venv/lib/python3.9/site-packages/nbclient/client.py", line 559, in async_execute
    await self.async_execute_cell(
  File "/home/flavus/Projects/phd/venv/lib/python3.9/site-packages/nbclient/client.py", line 854, in async_execute_cell
    self._check_raise_for_error(cell, exec_reply)
  File "/home/flavus/Projects/phd/venv/lib/python3.9/site-packages/nbclient/client.py", line 756, in _check_raise_for_error
    raise CellExecutionError.from_cell_and_msg(cell, exec_reply_content)
nbclient.exceptions.CellExecutionError: An error occurred while executing the following cell:
------------------
from phd.methods.tables import display_mprage_counts

display_mprage_counts()
------------------

[0;31m---------------------------------------------------------------------------[0m
[0;31mTypeError[0m                                 Traceback (most recent call last)
[0;32m/tmp/ipykernel_289108/4223800865.py[0m in [0;36m<module>[0;34m[0m
[1;32m      1[0m [0;32mfrom[0m [0mphd[0m[0;34m.[0m[0mmethods[0m[0;34m.[0m[0mtables[0m [0;32mimport[0m [0mdisplay_mprage_counts[0m[0;34m[0m[0;34m[0m[0m
[1;32m      2[0m [0;34m[0m[0m
[0;32m----> 3[0;31m [0mdisplay_mprage_counts[0m[0;34m([0m[0;34m)[0m[0;34m[0m[0;34m[0m[0m
[0m
[0;32m~/Projects/phd/src/phd/methods/tables.py[0m in [0;36mdisplay_mprage_counts[0;34m(csv_path, hide_index)[0m
[1;32m     21[0m     [0mtotal_count[0m [0;34m=[0m [0mdf[0m[0;34m[[0m[0;34m"Count"[0m[0;34m][0m[0;34m.[0m[0msum[0m[0;34m([0m[0;34m)[0m[0;34m[0m[0;34m[0m[0m
[1;32m     22[0m     return (
[0;32m---> 23[0;31m         style_df(
[0m[1;32m     24[0m             [0mdf[0m[0;34m,[0m[0;34m[0m[0;34m[0m[0m
[1;32m     25[0m             [0mhide_index[0m[0;34m=[0m[0mhide_index[0m[0;34m,[0m[0;34m[0m[0;34m[0m[0m

[0;31mTypeError[0m: style_df() got an unexpected keyword argument 'format'
TypeError: style_df() got an unexpected keyword argument 'format'

